Workbook

Sheet Credit_Rates
B2: Capella Credit Rates
B3: Update columns G and H with rates from your Capella console before use.
B4: All values in columns G and H are placeholders only.
B5: # | C5: Instance | D5: vCPU | E5: RAM (GB) | F5: Max Disk (TB) | G5: Credits / hr (Developer Pro) | H5: Credits / hr (Enterprise) | I5: Notes
B6: 1 | C6: m5.xlarge | D6: 4 | E6: 16 | F6: 1 | G6: 1.5 | H6: 2.1 | I6: Dev/test, light workloads
B7: 2 | C7: m5.2xlarge | D7: 8 | E7: 32 | F7: 2 | G7: 3 | H7: 4.2 | I7: Small-medium production
B8: 3 | C8: m5.4xlarge | D8: 16 | E8: 64 | F8: 4 | G8: 6 | H8: 8.4 | I8: Medium production
B9: 4 | C9: m5.8xlarge | D9: 32 | E9: 128 | F9: 8 | G9: 12 | H9: 16.8 | I9: Large production
B10: 5 | C10: m5.12xlarge | D10: 48 | E10: 192 | F10: 12 | G10: 18 | H10: 25.2 | I10: High-performance
B11: 6 | C11: m5.16xlarge | D11: 64 | E11: 256 | F11: 16 | G11: 24 | H11: 33.6 | I11: Enterprise-scale

Sheet Inputs
B2: Capella Cluster Sizing — Inputs
B3: Enter values in the yellow cells. Formulas and results are in the Results and Dashboard tabs.
B5: General
B6: Deployment Mode | C6: MDS | E6: MDS = dedicated nodes per service | Co-located = all on shared nodes | Hybrid = data dedicated, rest shared
B7: Service Tier | C7: Developer Pro | E7: Affects which credit rate column is used from Credit_Rates tab
B8: Current Credit Balance | C8: 75000 | D8: credits | E8: Available credits at start of planning period
B9: Planning Horizon | C9: 12 | D9: months | E9: Projection window for runway and balance forecasts
B11: Data Service
B12: Document Count | C12: 1000000 | D12: docs | E12: Total number of documents across all buckets
B13: Avg Document Size | C13: 10000 | D13: bytes | E13: Average size of a single document (value only, not key)
B14: Avg ID / Key Size | C14: 50 | D14: bytes | E14: Average document key length in bytes
B15: Replica Count | C15: 1 | E15: 1 = standard HA | 2 = extra durability
B16: Working Set % | C16: 20 | D16: % | E16: Percentage of dataset that must reside in RAM at all times
B17: Compression Ratio | C17: 0.7 | E17: 0.7 = Snappy estimate for JSON | Use 1.0 for already-compressed binaries
B18: Storage Engine | C18: Magma | E18: Magma = append multiplier 2.2 | Couchstore = 3.0
B19: Documents Deleted / Day | C19: 5000 | D19: docs | E19: Deletions + TTL expirations per day — affects tombstone space
B20: Purge Interval | C20: 3 | D20: days | E20: Metadata purge interval — default is 3 days
B22: Index Service
B23: Number of Index Entries | C23: 10000000 | D23: entries | E23: Total entries across all indexes (not unique documents)
B24: Avg Secondary Key Size | C24: 50 | D24: bytes | E24: Average size of the indexed field value in bytes
B25: Number of Indexes | C25: 5 | E25: Total GSI indexes in the cluster
B26: Index Storage Mode | C26: Standard GSI (Plasma) | E26: Plasma = Standard GSI, 20% resident | Nitro = Memory-Optimized, 100% resident
B28: Query Service
B29: Target Concurrent Queries | C29: 50 | E29: Peak simultaneous N1QL / SQL++ queries — Couchbase allows CPU cores x 4 concurrent queries per node
B31: Eventing Service
B32: Number of Eventing Functions | C32: 3 | E32: Number of deployed Eventing functions
B33: Mutation Rate | C33: 20000 | D33: mutations/sec | E33: Expected peak mutations per second across all buckets
B34: Timer Usage | C34: No | E34: Do any functions use timers? Each active timer consumes ~1 KB of storage
B35: Active Timer Count | C35: 0 | D35: timers | E35: Number of concurrently active timers (if Timer Usage = Yes)
B38: Sizing constants (per Couchbase documentation)
B39: RAM overhead: 25% | High water mark: 85% | Metadata per document: 56 bytes
B40: Index overhead: 25% | Plasma working set: 20% | Nitro working set: 100%
B41: Eventing: 8 vCPU recommended per node | ~50,000 mutations/sec per node | 100 MB storage per function
B42: Co-located RAM allocation: 85% of instance RAM available for Couchbase services

Sheet Results
B2: Sizing Results
B3: =CONCATENATE("Mode: ",Inputs!C6," | Tier: ",Inputs!C7) -> Mode: MDS | Tier: Developer Pro
B5: A. Sizing Requirements (Couchbase official formulas)
B6: Metric | C6: Value | D6: Unit | E6: Formula basis
B7: Data Service — RAM Required | C7: =((Inputs!C12*(56+Inputs!C14)*(1+Inputs!C15)+Inputs!C12*Inputs!C13*(1+Inputs!C15)*(Inputs!C16/100))*1.25/0.85)/1073741824 -> 5.7687216 | D7: GB | E7: (metadata + working set) x 1.25 overhead / 0.85 high water mark
B8: Data Service — Disk Required | C8: =(((Inputs!C12*Inputs!C13*Inputs!C17*(1+Inputs!C15)+Inputs!C12*56+Inputs!C12*Inputs!C14)*IF(Inputs!C18="Magma",2.2,3))+(Inputs!C14+60)*Inputs!C20*(Inputs!C15+1)*Inputs!C19)/1073741824 -> 28.904993 | D8: GB | E8: (dataset x copies + metadata + keys) x append-multiplier + tombstones
B9: Index Service — RAM Required | C9: =IF(Inputs!C26="Memory-Optimized (Nitro)",Inputs!C23*(120+Inputs!C14+Inputs!C24)*1.25/1073741824*Inputs!C25,Inputs!C23*(120+Inputs!C14+Inputs!C24)*2*1.25*0.2/1073741824*Inputs!C25) -> 5.1222742 | D9: GB | E9: Nitro: 100% resident x 1.25 | Plasma: x2 x 1.25 x 20% resident | x num indexes
B10: Query Service — vCPUs Required | C10: =CEILING(Inputs!C29/4,1) -> 13 | D10: vCPUs | E10: Couchbase: CPU cores x 4 = max concurrent queries
B11: Eventing — Nodes Required (min 2) | C11: =MAX(CEILING(Inputs!C33/50000,1),2) -> 2 | D11: nodes | E11: ~50,000 mutations/sec per 8-vCPU node | minimum 2 for HA
B12: Eventing — Storage Required | C12: =Inputs!C32*100+IF(Inputs!C34="Yes",Inputs!C35*0.001,0) -> 300 | D12: MB | E12: 100 MB per function + 1 KB per active timer
B14: B. Instance Selection (choose per service)
B15: Service | C15: Instance | D15: RAM (GB) | E15: vCPU | F15: Max Disk (TB) | G15: Credits / hr
B16: Data Service | C16: m5.2xlarge | D16: =INDEX(Credit_Rates!$E$6:$E$11,MATCH(C16,Credit_Rates!$C$6:$C$11,0)) -> 32 | E16: =INDEX(Credit_Rates!$D$6:$D$11,MATCH(C16,Credit_Rates!$C$6:$C$11,0)) -> 8 | F16: =INDEX(Credit_Rates!$F$6:$F$11,MATCH(C16,Credit_Rates!$C$6:$C$11,0)) -> 2 | G16: =IF(Inputs!$C$7="Developer Pro",INDEX(Credit_Rates!$G$6:$G$11,MATCH(C16,Credit_Rates!$C$6:$C$11,0)),INDEX(Credit_Rates!$H$6:$H$11,MATCH(C16,Credit_Rates!$C$6:$C$11,0))) -> 3
B17: Index Service | C17: m5.2xlarge | D17: =INDEX(Credit_Rates!$E$6:$E$11,MATCH(C17,Credit_Rates!$C$6:$C$11,0)) -> 32 | E17: =INDEX(Credit_Rates!$D$6:$D$11,MATCH(C17,Credit_Rates!$C$6:$C$11,0)) -> 8 | F17: =INDEX(Credit_Rates!$F$6:$F$11,MATCH(C17,Credit_Rates!$C$6:$C$11,0)) -> 2 | G17: =IF(Inputs!$C$7="Developer Pro",INDEX(Credit_Rates!$G$6:$G$11,MATCH(C17,Credit_Rates!$C$6:$C$11,0)),INDEX(Credit_Rates!$H$6:$H$11,MATCH(C17,Credit_Rates!$C$6:$C$11,0))) -> 3
B18: Query Service | C18: m5.xlarge | D18: =INDEX(Credit_Rates!$E$6:$E$11,MATCH(C18,Credit_Rates!$C$6:$C$11,0)) -> 16 | E18: =INDEX(Credit_Rates!$D$6:$D$11,MATCH(C18,Credit_Rates!$C$6:$C$11,0)) -> 4 | F18: =INDEX(Credit_Rates!$F$6:$F$11,MATCH(C18,Credit_Rates!$C$6:$C$11,0)) -> 1 | G18: =IF(Inputs!$C$7="Developer Pro",INDEX(Credit_Rates!$G$6:$G$11,MATCH(C18,Credit_Rates!$C$6:$C$11,0)),INDEX(Credit_Rates!$H$6:$H$11,MATCH(C18,Credit_Rates!$C$6:$C$11,0))) -> 1.5
B19: Eventing Service | C19: m5.xlarge | D19: =INDEX(Credit_Rates!$E$6:$E$11,MATCH(C19,Credit_Rates!$C$6:$C$11,0)) -> 16 | E19: =INDEX(Credit_Rates!$D$6:$D$11,MATCH(C19,Credit_Rates!$C$6:$C$11,0)) -> 4 | F19: =INDEX(Credit_Rates!$F$6:$F$11,MATCH(C19,Credit_Rates!$C$6:$C$11,0)) -> 1 | G19: =IF(Inputs!$C$7="Developer Pro",INDEX(Credit_Rates!$G$6:$G$11,MATCH(C19,Credit_Rates!$C$6:$C$11,0)),INDEX(Credit_Rates!$H$6:$H$11,MATCH(C19,Credit_Rates!$C$6:$C$11,0))) -> 1.5
B21: C. MDS — Dedicated Nodes per Service
B22: Service | C22: Nodes | D22: Credits / hr | E22: Credits / Month
B23: Data Service | C23: =MAX(CEILING($C$7/$D$16,1),CEILING($C$8/($F$16*1000),1),3) -> 3 | D23: =C23*$G$16 -> 9 | E23: =D23*24*30 -> 6480
B24: Index Service | C24: =MAX(CEILING($C$9/$D$17,1),2) -> 2 | D24: =C24*$G$17 -> 6 | E24: =D24*24*30 -> 4320
B25: Query Service | C25: =MAX(CEILING($C$10/$E$18,1),2) -> 4 | D25: =C25*$G$18 -> 6 | E25: =D25*24*30 -> 4320
B26: Eventing Service | C26: =$C$11 -> 2 | D26: =C26*$G$19 -> 3 | E26: =D26*24*30 -> 2160
B27: Total | C27: =SUM(C23:C26) -> 11 | D27: =SUM(D23:D26) -> 24 | E27: =SUM(E23:E26) -> 17280
B29: D. Co-located — All Services on Shared Nodes
B30: Nodes are sized to the largest single-service requirement. Combined Data + Index RAM must fit within node RAM (85% allocation).
B31: Pool | C31: Nodes | D31: Credits / hr | E31: Credits / Month
B32: All Services Combined | C32: =MAX(C23,C24,C25,C26,CEILING(($C$7+$C$9)/($D$16*0.85),1)) -> 4 | D32: =C32*G16 -> 12 | E32: =D32*24*30 -> 8640
B34: E. Hybrid — Data Dedicated | Index + Query + Eventing Shared
B35: Pool | C35: Nodes | D35: Credits / hr | E35: Credits / Month
B36: Data Pool (dedicated) | C36: =C23 -> 3 | D36: =C36*G16 -> 9 | E36: =D36*24*30 -> 6480
B37: Shared Pool (Index + Query + Eventing) | C37: =MAX(C24,C25,C26,CEILING($C$9/$D$17,1),2) -> 4 | D37: =C37*G17 -> 12 | E37: =D37*24*30 -> 8640
B38: Total | C38: =C36+C37 -> 7 | D38: =D36+D37 -> 21 | E38: =E36+E37 -> 15120
B40: F. Runway Projection (based on selected mode)
B41: Metric | C41: Value
B42: Credits / Month (selected mode) | C42: =IF(Inputs!C6="MDS",E27,IF(Inputs!C6="Co-located",E32,E38)) -> 17280 | D42: credits/mo
B43: Available Credits | C43: =Inputs!C8 -> 75000 | D43: credits
B44: Projected Runway | C44: =IFERROR(C43/C42,0) -> 4.3402778 | D44: months
B45: Projected Expiry Date | C45: =IFERROR(TEXT(TODAY()+C44*30,"YYYY-MM-DD"),"N/A") -> 2026-09-19
B47: Balance Forecast
B48: Month | C48: Remaining Balance
...

Sheet Dashboard
B2: Capella Cluster Sizing — Dashboard
B3: =CONCATENATE(Inputs!C6," mode selected | ",Inputs!C7," | Balance: ",TEXT(Inputs!C8,"#,##0")," credits") -> MDS mode selected | Developer Pro | Balance: 75,000 credits
B5: Three-Mode Comparison
B6: Metric | C6: MDS (Dedicated) | D6: Co-located | E6: Hybrid | F6: Notes
B7: Total Nodes | C7: =Results!C27 -> 11 | D7: =Results!C32 -> 4 | E7: =Results!C38 -> 7 | F7: Co-located: all services share same nodes
B8: Credits / hr | C8: =Results!D27 -> 24 | D8: =Results!D32 -> 12 | E8: =Results!D38 -> 21
B9: Credits / Month | C9: =Results!E27 -> 17280 | D9: =Results!E32 -> 8640 | E9: =Results!E38 -> 15120 | F9: Based on selected instance types in Results tab
B10: Credits / Year | C10: =Results!E27*12 -> 207360 | D10: =Results!E32*12 -> 103680 | E10: =Results!E38*12 -> 181440
B11: Monthly Savings vs MDS | C11: — | D11: =Results!E27-Results!E32 -> 8640 | E11: =Results!E27-Results!E38 -> 2160 | F11: Positive = cheaper than MDS
B12: Projected Runway (months) | C12: =IFERROR(Inputs!C8/Results!E27,0) -> 4.3402778 | D12: =IFERROR(Inputs!C8/Results!E32,0) -> 8.6805556 | E12: =IFERROR(Inputs!C8/Results!E38,0) -> 4.9603175 | F12: Based on credit balance in Inputs!C8
B14: =CONCATENATE("Selected mode: ",Inputs!C6," — Monthly burn: ",TEXT(IF(Inputs!C6="MDS",Results!E27,IF(Inputs!C6="Co-located",Results!E32,Results!E38)),"#,##0")," credits/month — Runway: ",TEXT(Results!C44,"#,##0.0")," months") -> Selected mode: MDS — Monthly burn: 17,280 credits/month — Runway: 4.3 months
B17: Credit Balance Forecast (selected mode)
B18: Month | C18: Remaining Balance | D18: Status
B19: Month 3 | C19: =Results!C49 -> 23160 | D19: =IF(Results!C49>0,"Sufficient","Depleted") -> Sufficient
B20: Month 6 | C20: =Results!C50 -> 0 | D20: =IF(Results!C50>0,"Sufficient","Depleted") -> Depleted
B21: Month 9 | C21: =Results!C51 -> 0 | D21: =IF(Results!C51>0,"Sufficient","Depleted") -> Depleted
B22: Month 12 | C22: =Results!C52 -> 0 | D22: =IF(Results!C52>0,"Sufficient","Depleted") -> Depleted
B23: Month 18 | C23: =Results!C53 -> 0 | D23: =IF(Results!C53>0,"Sufficient","Depleted") -> Depleted
B24: Month 24 | C24: =Results!C54 -> 0 | D24: =IF(Results!C54>0,"Sufficient","Depleted") -> Depleted
B27: Deployment Mode Guide
B28: MDS (Dedicated) | C28: Production, latency-sensitive, payments / FedNow workloads | E28: Highest node count, highest credits — best isolation and independent scaling
B29: Co-located | C29: Dev/test, small datasets, budget-constrained | E29: Fewest nodes — but services compete for RAM and CPU on the same hardware
B30: Hybrid | C30: Mid-range production — data workload dominates | E30: Data service isolated; Index/Query/Eventing share a pool — good balance of cost and control
